<mujoco model="Motor Control"> 
    <option timestep="0.005" iterations="50" solver="Newton" tolerance="1e-10"/>
    <option gravity = "0 0 -9.81">
        <flag contact="enable" />
    </option >
    <visual>
        <rgba haze=".3 .3 .3 1"/>
    </visual>
    <default>
        <joint type="hinge" pos="0 0 0" axis="1 0 0" limited="false" damping="0.02"/>
    </default>
    <asset>
        <texture type="skybox" builtin="gradient" rgb1="0.6 0.6 0.6" rgb2="0 0 0" width="512" height="512"/>
        <texture name="texplane" type="2d" builtin="checker" rgb1=".25 .25 .25" rgb2=".3 .3 .3" width="512" height="512" mark="cross" markrgb=".8 .8 .8"/>
        <material name="matplane" reflectance="0.3" texture="texplane" texrepeat="1 1" texuniform="true"/>
    </asset>
    <worldbody>
        <geom name="floor" pos="0 0 -0.5" size="0 0 1" type="plane" material="matplane"/>
        <light directional="true" diffuse=".5 .5 .5" specular=".2 .2 .2" pos="0 0 5" dir="0 0 -1"/>
        <!-- <geom name = "motor_body" type = "cylinder" size = "0.4625 0.21" rgba = "0 0 1 1" quat="0 0.701 0 0.701" pos = "0.22 0 0" friction="0"/> -->
        <body>
            <geom name = "motor_body" type = "cylinder" size = "0.04625 0.021" rgba = "0 0 1 1" quat="0 0.701 0 0.701" pos = "0.02258 0 0" friction="0" gap="0.01"/>
            <body>
                <body pos = "0 0.029 0">
                    <geom name="load_arm" type = "box" size=".001588 0.090744 0.008625" rgba=".5 .1 .1 1" pos = "0 0.090744 0" density = "2710"/>
                    <!-- <geom name="load_arm" type="capsule" size="0.045" fromto="0 0.5 0 0 0 0"  rgba=".5 .1 .1 1"/> -->
                    <body pos="-0.0055 0.181488 0.0">
                        <geom name="weight" type="box" size="0.0055 0.0255 0.0305" density = "7750"/>
                        <site name = "mount"/>
                    </body>
                </body>
                <joint name="motor"/>
                <geom name="motor" type="cylinder" pos="0 0 0" size=".029 .001588" rgba=".5 .1 .8 .5" quat="0 0.701 0 0.701" group="1" friction="0" gap="0.01" density = "2710"/>
            </body>
        </body>
    </worldbody>
    <actuator>
        <motor name="torque" joint="motor"  gear="1" ctrllimited="true" ctrlrange="-4 4"/>
        <position name="position_servo" joint="motor" kp="0"/>
        <velocity name="velocity_servo" joint="motor" kv="0.1"/>
   </actuator>

    <sensor>
      <torque name = "torque_sensor" site= "mount"/>
   </sensor>
   <keyframe>
        <key name="spinning" time="0" qpos="-1.6" qvel = "0"/>
   </keyframe>

</mujoco>